<?xml version="1.0" ?>
<!-- This URDF was automatically created by SolidWorks to URDF Exporter! Originally created by Stephen Brawner (brawner@gmail.com) 
     Commit Version: 1.6.0-4-g7f85cfe  Build Version: 1.6.7995.38578
     For more information, please see http://wiki.ros.org/sw_urdf_exporter -->
<robot
  name="project_1_group_2" xmlns:xacro="http://ros.org/wiki/xacro">




  <xacro:macro name="red_color">
      <visual>
      <material>
          <ambient>1 0.168627450980392 0.168627450980392 1</ambient>
          <diffuse>1 0.168627450980392 0.168627450980392 1</diffuse>
          <specular>0.1 0.1 0.1 1</specular>
          <emissive>0 0 0 0</emissive>
      </material>
      </visual>
  </xacro:macro>
  
  <xacro:macro name="grey_color">
      <visual>
      <material>
          <ambient>0.8 0.558823529411765 0.1 1</ambient>
          <diffuse>0.8 0.558823529411765 0.1 1</diffuse>
          <specular>0.1 0.1 0.1 1</specular>
          <emissive>0 0 0 0</emissive>
      </material>
      </visual>
  </xacro:macro>

  <xacro:macro name="black_color">
      <visual>
      <material>
          <ambient>0.6 0.6 0.6 1</ambient>
          <diffuse>0.6 0.6 0.6 1</diffuse>
          <specular>0.1 0.1 0.1 1</specular>
          <emissive>0 0 0 0</emissive>
      </material>
      </visual>
  </xacro:macro>


  # Add this before base link
  <link name="dummy_link"></link>
  

  <link
    name="base_link">
    <inertial>
      <origin
        xyz="0.219542184923656 0.253147662670064 0.488981343790689"
        rpy="0 0 0" />
      <mass
        value="1" />
      <inertia
        ixx="3.47686976214323"
        ixy="1.28363813560472E-06"
        ixz="-8.67881754875189E-06"
        iyy="4.33091580677011"
        iyz="-0.0565812633669083"
        izz="1.5150564663539" />
    </inertial>
    <visual>
      <origin
        xyz="0 0 0"
        rpy="0 0 0" />
      <geometry>
        <mesh
          filename="package://project_1_group_2/meshes/base_link.STL" />
      </geometry>
      <material
        name="">
        <color
          rgba="1 0.168627450980392 0.168627450980392 1" />
      </material>
    </visual>
    <collision>
      <origin
        xyz="0 0 0"
        rpy="0 0 0" />
      <geometry>
        <mesh
          filename="package://project_1_group_2/meshes/base_link.STL" />
      </geometry>
    </collision>
  </link>

    # Add this after base link
  <joint 
    name="dummy_joint" 
    type="fixed">
    <origin 
      rpy="0 0 0" 
      xyz="0 0 0" />
    <parent 
      link="dummy_link"/>
    <child 
      link="base_link"/>
  </joint>

  <link
    name="steering_wheel_1">
    <inertial>
      <origin
        xyz="2.86075080291326E-08 -0.0749063419355981 -0.00254051949689645"
        rpy="0 0 0" />
      <mass
        value="5.295424107267105" />
      <inertia
        ixx="0.000710809060839366"
        ixy="-1.53957020615015E-10"
        ixz="-3.53322320543782E-10"
        iyy="0.000104054571155282"
        iyz="3.85934455800395E-05"
        izz="0.000690101015602262" />
    </inertial>
    <visual>
      <origin
        xyz="0 0 0"
        rpy="0 0 0" />
      <geometry>
        <mesh
          filename="package://project_1_group_2/meshes/steering_wheel_1.STL" />
      </geometry>
      <material
        name="">
        <color
          rgba="1 0.168627450980392 0.168627450980392 1" />
      </material>
    </visual>
    <collision>
      <origin
        xyz="0 0 0"
        rpy="0 0 0" />
      <geometry>
        <mesh
          filename="package://project_1_group_2/meshes/steering_wheel_1.STL" />
      </geometry>
    </collision>
  </link>
  <joint
    name="steering_joint_1"
    type="revolute">
    <origin
      xyz="0.070952 -0.7342 0.035594"
      rpy="-1.5708 0 -1.5708" />
    <parent
      link="base_link" />
    <child
      link="steering_wheel_1" />
    <axis
      xyz="0 1 0" />
    <limit
      lower="-3.14"
      upper="3.14"
      effort="10"
      velocity="10" />
  </joint>
  <link
    name="wheel_1">
    <inertial>
      <origin
        xyz="0 0.0251005990323743 0"
        rpy="0 0 0" />
      <mass
        value="0.217134053712094" />
      <inertia
        ixx="0.000126052696684198"
        ixy="-3.30911918449584E-21"
        ixz="6.7762635780344E-21"
        iyy="0.000159854355976214"
        iyz="-7.03947290074457E-21"
        izz="0.000126052696684198" />
    </inertial>
    <visual>
      <origin
        xyz="0 0 0"
        rpy="0 0 0" />
      <geometry>
        <mesh
          filename="package://project_1_group_2/meshes/wheel_1.STL" />
      </geometry>
      <material
        name="">
        <color
          rgba="0.498039215686275 0.498039215686275 0.498039215686275 1" />
      </material>
    </visual>
    <collision>
      <origin
        xyz="0 0 0"
        rpy="0 0 0" />
      <geometry>
        <mesh
          filename="package://project_1_group_2/meshes/wheel_1.STL" />
      </geometry>
    </collision>
  </link>
  <joint
    name="wheel_1_joint"
    type="continuous">
    <origin
      xyz="0 -0.0234950000000001 -0.040767"
      rpy="-1.5707963267949 0 -1.16226628629428" />
    <parent
      link="steering_wheel_1" />
    <child
      link="wheel_1" />
    <axis
      xyz="0 1 0" />
  </joint>
  <link
    name="tire_1">
    <inertial>
      <origin
        xyz="0 0.0380963424606702 -6.9367125220543E-06"
        rpy="0 0 0" />
      <mass
        value="1.9636352752673" />
      <inertia
        ixx="0.00664149361787531"
        ixy="3.02337822610582E-19"
        ixz="2.16840434497101E-19"
        iyy="0.0114725337233255"
        iyz="5.01717636400841E-07"
        izz="0.00664244711710664" />
      </inertial>
    <visual>
      <origin
        xyz="0 0 0"
        rpy="0 0 0" />
      <geometry>
        <mesh
          filename="package://project_1_group_2/meshes/tire_1.STL" />
      </geometry>
      <material
        name="">
        <color
          rgba="0.6 0.6 0.6 1" />
      </material>
    </visual>
    <collision>
      <origin
        xyz="0 0 0"
        rpy="0 0 0" />
      <geometry>
        <mesh
          filename="package://project_1_group_2/meshes/tire_1.STL" />
      </geometry>
    </collision>
  </link>
  <joint
    name="tire_1_joint"
    type="fixed">
    <origin
      xyz="0 -0.0127000000000001 0"
      rpy="0 0 0" />
    <parent
      link="wheel_1" />
    <child
      link="tire_1" />
    <axis
      xyz="0 0 0" />
  </joint>
  <link
    name="steering_wheel_2">
    <inertial>
      <origin
        xyz="2.86075079181103E-08 0.074906341935598 0.00254051949689649"
        rpy="0 0 0" />
      <mass
        value="5.295424107267105" />
      <inertia
        ixx="0.000710809060839365"
        ixy="1.53957021878157E-10"
        ixz="3.53322320610221E-10"
        iyy="0.000104054571155282"
        iyz="3.85934455800397E-05"
        izz="0.000690101015602261" />
    </inertial>
    <visual>
      <origin
        xyz="0 0 0"
        rpy="0 0 0" />
      <geometry>
        <mesh
          filename="package://project_1_group_2/meshes/steering_wheel_2.STL" />
      </geometry>
      <material
        name="">
        <color
          rgba="1 0.168627450980392 0.168627450980392 1" />
      </material>
    </visual>
    <collision>
      <origin
        xyz="0 0 0"
        rpy="0 0 0" />
      <geometry>
        <mesh
          filename="package://project_1_group_2/meshes/steering_wheel_2.STL" />
      </geometry>
    </collision>
  </link>
  <joint
    name="steering_joint_2"
    type="revolute">
    <origin
      xyz="0.36813 -0.7342 0.035594"
      rpy="1.5708 0 1.5708" />
    <parent
      link="base_link" />
    <child
      link="steering_wheel_2" />
    <axis
      xyz="0 1 0" />
    <limit
      lower="-3.14"
      upper="3.14"
      effort="100"
      velocity="10" />
  </joint>
  <link
    name="wheel_2">
    <inertial>
      <origin
        xyz="0 0.0251005990323743 0"
        rpy="0 0 0" />
      <mass
        value="0.217134053712094" />
      <inertia
        ixx="0.000126052696684198"
        ixy="-2.42959470068895E-21"
        ixz="0"
        iyy="0.000159854355976214"
        iyz="-1.47427383956479E-20"
        izz="0.000126052696684198" />
    </inertial>
    <visual>
      <origin
        xyz="0 0 0"
        rpy="0 0 0" />
      <geometry>
        <mesh
          filename="package://project_1_group_2/meshes/wheel_2.STL" />
      </geometry>
      <material
        name="">
        <color
          rgba="0.498039215686275 0.498039215686275 0.498039215686275 1" />
      </material>
    </visual>
    <collision>
      <origin
        xyz="0 0 0"
        rpy="0 0 0" />
      <geometry>
        <mesh
          filename="package://project_1_group_2/meshes/wheel_2.STL" />
      </geometry>
    </collision>
  </link>
  <joint
    name="wheel_2_joint"
    type="continuous">
    <origin
      xyz="0 0.0234950000000022 0.0407670000000003"
      rpy="1.5707963267949 0 0.927408187420047" />
    <parent
      link="steering_wheel_2" />
    <child
      link="wheel_2" />
    <axis
      xyz="0 1 0" />
  </joint>
  <link
    name="tire_2">
    <inertial>
      <origin
        xyz="-5.55111512312578E-17 0.0380963424606702 -6.93671252216532E-06"
        rpy="0 0 0" />
      <mass
        value="1.9636352752673" />
      <inertia
        ixx="0.00664149361787532"
        ixy="5.1086674631275E-20"
        ixz="-2.16840434497101E-19"
        iyy="0.0114725337233255"
        iyz="5.01717636401181E-07"
        izz="0.00664244711710664" />
    </inertial>
    <visual>
      <origin
        xyz="0 0 0"
        rpy="0 0 0" />
      <geometry>
        <mesh
          filename="package://project_1_group_2/meshes/tire_2.STL" />
      </geometry>
      <material
        name="">
        <color
          rgba="0.6 0.6 0.6 1" />
      </material>
    </visual>
    <collision>
      <origin
        xyz="0 0 0"
        rpy="0 0 0" />
      <geometry>
        <mesh
          filename="package://project_1_group_2/meshes/tire_2.STL" />
      </geometry>
    </collision>
  </link>
  <joint
    name="tire_2_joint"
    type="fixed">
    <origin
      xyz="0 -0.0126999999999999 0"
      rpy="0 0 0" />
    <parent
      link="wheel_2" />
    <child
      link="tire_2" />
    <axis
      xyz="0 0 0" />
  </joint>
  <link
    name="drive_wheel_1">
    <inertial>
      <origin
        xyz="0 -0.00140110038134092 0"
        rpy="0 0 0" />
      <mass
        value="0.217134053712094" />
      <inertia
        ixx="0.000126052696684197"
        ixy="3.65980047539585E-21"
        ixz="-6.7762635780344E-21"
        iyy="0.000159854355976214"
        iyz="-7.39817207392887E-22"
        izz="0.000126052696684197" />
    </inertial>
    <visual>
      <origin
        xyz="0 0 0"
        rpy="0 0 0" />
      <geometry>
        <mesh
          filename="package://project_1_group_2/meshes/drive_wheel_1.STL" />
      </geometry>
      <material
        name="">
        <color
          rgba="0.498039215686275 0.498039215686275 0.498039215686275 1" />
      </material>
    </visual>
    <collision>
      <origin
        xyz="0 0 0"
        rpy="0 0 0" />
      <geometry>
        <mesh
          filename="package://project_1_group_2/meshes/drive_wheel_1.STL" />
      </geometry>
    </collision>
  </link>
  <joint
    name="drive_wheel_1_joint"
    type="continuous">
    <origin
      xyz="0 -0.2262 0.061675"
      rpy="0 -1.0561 1.5708" />
    <parent
      link="base_link" />
    <child
      link="drive_wheel_1" />
    <axis
      xyz="0 1 0" />
  </joint>
  <link
    name="drive_tire_1">
    <inertial>
      <origin
        xyz="2.08166817117217E-17 0.0380963424606702 -6.93671252210981E-06"
        rpy="0 0 0" />
      <mass
        value="1.9636352752673" />
      <inertia
        ixx="0.00664149361787532"
        ixy="6.09678433565884E-19"
        ixz="8.67361737988404E-19"
        iyy="0.0114725337233256"
        iyz="5.01717636401377E-07"
        izz="0.00664244711710664" />
    </inertial>
    <visual>
      <origin
        xyz="0 0 0"
        rpy="0 0 0" />
      <geometry>
        <mesh
          filename="package://project_1_group_2/meshes/drive_tire_1.STL" />
      </geometry>
      <material
        name="">
        <color
          rgba="0.6 0.6 0.6 1" />
      </material>
    </visual>
    <collision>
      <origin
        xyz="0 0 0"
        rpy="0 0 0" />
      <geometry>
        <mesh
          filename="package://project_1_group_2/meshes/drive_tire_1.STL" />
      </geometry>
    </collision>
  </link>
  <joint
    name="drive_tire_1_joint"
    type="fixed">
    <origin
      xyz="0 -0.0392016994137152 0"
      rpy="0 0 0" />
    <parent
      link="drive_wheel_1" />
    <child
      link="drive_tire_1" />
    <axis
      xyz="0 0 0" />
  </joint>
  <link
    name="drive_wheel_2">
    <inertial>
      <origin
        xyz="0 0.0251005990323744 0"
        rpy="0 0 0" />
      <mass
        value="0.217134053712094" />
      <inertia
        ixx="0.000126052696684197"
        ixy="-5.05000906564327E-21"
        ixz="1.01643953670516E-20"
        iyy="0.000159854355976214"
        iyz="3.01026101938204E-21"
        izz="0.000126052696684198" />
    </inertial>
    <visual>
      <origin
        xyz="0 0 0"
        rpy="0 0 0" />
      <geometry>
        <mesh
          filename="package://project_1_group_2/meshes/drive_wheel_2.STL" />
      </geometry>
      <material
        name="">
        <color
          rgba="0.498039215686275 0.498039215686275 0.498039215686275 1" />
      </material>
    </visual>
    <collision>
      <origin
        xyz="0 0 0"
        rpy="0 0 0" />
      <geometry>
        <mesh
          filename="package://project_1_group_2/meshes/drive_wheel_2.STL" />
      </geometry>
    </collision>
  </link>
  <joint
    name="drive_wheel_2_joint"
    type="continuous">
    <origin
      xyz="0.41258 -0.2262 0.061675"
      rpy="0 0.9434 -1.5708" />
    <parent
      link="base_link" />
    <child
      link="drive_wheel_2" />
    <axis
      xyz="0 1 0" />
  </joint>
  <link
    name="drive_tire_2">
    <inertial>
      <origin
        xyz="2.77555756156289E-17 0.0380963424606702 -6.93671252208206E-06"
        rpy="0 0 0" />
      <mass
        value="1.9636352752673" />
      <inertia
        ixx="0.00664149361787531"
        ixy="3.34048618573415E-19"
        ixz="6.50521303491303E-19"
        iyy="0.0114725337233255"
        iyz="5.0171763640111E-07"
        izz="0.00664244711710664" />
    </inertial>
    <visual>
      <origin
        xyz="0 0 0"
        rpy="0 0 0" />
      <geometry>
        <mesh
          filename="package://project_1_group_2/meshes/drive_tire_2.STL" />
      </geometry>
      <material
        name="">
        <color
          rgba="0.6 0.6 0.6 1" />
      </material>
    </visual>
    <collision>
      <origin
        xyz="0 0 0"
        rpy="0 0 0" />
      <geometry>
        <mesh
          filename="package://project_1_group_2/meshes/drive_tire_2.STL" />
      </geometry>
    </collision>
  </link>
  <joint
    name="drive_tire_2_joint"
    type="fixed">
    <origin
      xyz="0 -0.0126999999999999 0"
      rpy="3.14159265358979 0 3.14159265358979" />
    <parent
      link="drive_wheel_2" />
    <child
      link="drive_tire_2" />
    <axis
      xyz="0 0 0" />
  </joint>
  <link
    name="trailer">
    <inertial>
      <origin
        xyz="-2.14872014431267E-07 0.122240676993307 0.407195343988752"
        rpy="0 0 0" />
      <mass
        value="0.5" />
      <inertia
        ixx="0.106926412723749"
        ixy="-2.14631197863797E-08"
        ixz="-2.44065610516401E-07"
        iyy="0.204818186461493"
        iyz="-0.00158445646443877"
        izz="0.111161118457744" />
    </inertial>
    <visual>
      <origin
        xyz="0 0 0"
        rpy="0 0 0" />
      <geometry>
        <mesh
          filename="package://project_1_group_2/meshes/trailer.STL" />
      </geometry>
      <material
        name="">
        <color
          rgba="1 0.168627450980392 0.168627450980392 1" />
      </material>
    </visual>
    <collision>
      <origin
        xyz="0 0 0"
        rpy="0 0 0" />
      <geometry>
        <mesh
          filename="package://project_1_group_2/meshes/trailer.STL" />
      </geometry>
    </collision>
  </link>
  <joint
    name="trailer_joint"
    type="continuous">
    <origin
      xyz="0.21954 0.093844 0.041004"
      rpy="1.5708 0 3.1416" />
    <parent
      link="base_link" />
    <child
      link="trailer" />
    <axis
      xyz="0 1 0" />
  </joint>
  <link
    name="trailer_axle">
    <inertial>
      <origin
        xyz="0 -2.4980018054066E-16 0"
        rpy="0 0 0" />
      <mass
        value="0.388537069771013" />
      <inertia
        ixx="0.00709487470732702"
        ixy="4.69749067079451E-19"
        ixz="0"
        iyy="5.66992976163243E-05"
        iyz="2.01714087208509E-19"
        izz="0.00709487470732702" />
    </inertial>
    <visual>
      <origin
        xyz="0 0 0"
        rpy="0 0 0" />
      <geometry>
        <mesh
          filename="package://project_1_group_2/meshes/trailer_axle.STL" />
      </geometry>
      <material
        name="">
        <color
          rgba="0.498039215686275 0.498039215686275 0.498039215686275 1" />
      </material>
    </visual>
    <collision>
      <origin
        xyz="0 0 0"
        rpy="0 0 0" />
      <geometry>
        <mesh
          filename="package://project_1_group_2/meshes/trailer_axle.STL" />
      </geometry>
    </collision>
  </link>
  <joint
    name="trailer_axle_joint"
    type="continuous">
    <origin
      xyz="0 0.0312032475847516 0.422121581912838"
      rpy="0 -0.538949692004304 -1.5707963267949" />
    <parent
      link="trailer" />
    <child
      link="trailer_axle" />
    <axis
      xyz="0 1 0" />
  </joint>
  <link
    name="trailer_wheel_1">
    <inertial>
      <origin
        xyz="2.77555756156289E-17 -5.55111512312578E-17 0.01905"
        rpy="0 0 0" />
      <mass
        value="1.30378374657888" />
      <inertia
        ixx="0.00396064889398226"
        ixy="-2.16840434497101E-19"
        ixz="-1.43965953811448E-19"
        iyy="0.00396064889398226"
        iyz="2.23294111251937E-19"
        izz="0.00761008083736416" />
    </inertial>
    <visual>
      <origin
        xyz="0 0 0"
        rpy="0 0 0" />
      <geometry>
        <mesh
          filename="package://project_1_group_2/meshes/trailer_wheel_1.STL" />
      </geometry>
      <material
        name="">
        <color
          rgba="0.6 0.6 0.6 1" />
      </material>
    </visual>
    <collision>
      <origin
        xyz="0 0 0"
        rpy="0 0 0" />
      <geometry>
        <mesh
          filename="package://project_1_group_2/meshes/trailer_wheel_1.STL" />
      </geometry>
    </collision>
  </link>
  <joint
    name="trailer_wheel_1_joint"
    type="fixed">
    <origin
      xyz="0 0.2159 0"
      rpy="-1.5707963267949 0 0" />
    <parent
      link="trailer_axle" />
    <child
      link="trailer_wheel_1" />
    <axis
      xyz="0 0 0" />
  </joint>
  <link
    name="trailer_wheel_2">
    <inertial>
      <origin
        xyz="5.55111512312578E-17 5.55111512312578E-17 0.01905"
        rpy="0 0 0" />
      <mass
        value="1.30378374657888" />
      <inertia
        ixx="0.00396064889398225"
        ixy="3.25260651745651E-19"
        ixz="-1.14918482212615E-18"
        iyy="0.00396064889398226"
        iyz="-5.07286706220775E-18"
        izz="0.00761008083736415" />
    </inertial>
    <visual>
      <origin
        xyz="0 0 0"
        rpy="0 0 0" />
      <geometry>
        <mesh
          filename="package://project_1_group_2/meshes/trailer_wheel_2.STL" />
      </geometry>
      <material
        name="">
        <color
          rgba="0.6 0.6 0.6 1" />
      </material>
    </visual>
    <collision>
      <origin
        xyz="0 0 0"
        rpy="0 0 0" />
      <geometry>
        <mesh
          filename="package://project_1_group_2/meshes/trailer_wheel_2.STL" />
      </geometry>
    </collision>
  </link>
  <joint
    name="trailer_wheel_2_joint"
    type="fixed">
    <origin
      xyz="0 -0.2159 0"
      rpy="-1.5707963267949 0 3.14159265358979" />
    <parent
      link="trailer_axle" />
    <child
      link="trailer_wheel_2" />
    <axis
      xyz="0 0 0" />
  </joint>
    <link
    name="lidar_link">
    <inertial>
      <origin
        xyz="0 0.00127000000000005 0"
        rpy="0 0 0" />
      <mass
        value="0.00514814798763055" />
      <inertia
        ixx="8.33112604888014E-07"
        ixy="-3.20922964057601E-40"
        ixz="0"
        iyy="1.66068957784986E-06"
        iyz="2.8186396765545E-40"
        izz="8.33112604888014E-07" />
    </inertial>
    <visual>
      <origin
        xyz="0 0 0"
        rpy="0 0 0" />
      <geometry>
        <mesh
          filename="package://project_1_group_2/meshes/lidar_link.STL" />
      </geometry>
      <material
        name="">
        <color
          rgba="0.792156862745098 0.819607843137255 0.933333333333333 1" />
      </material>
    </visual>
    <collision>
      <origin
        xyz="0 0 0"
        rpy="0 0 0" />
      <geometry>
        <mesh
          filename="package://project_1_group_2/meshes/lidar_link.STL" />
      </geometry>
    </collision>
  </link>
  <joint
    name="lidar_joint"
    type="continuous">
    <origin
      xyz="0.219541699413715 -0.521188368096002 0.439623181973066"
      rpy="1.5707963267949 0 0" />
    <parent
      link="base_link" />
    <child
      link="lidar_link" />
    <axis
      xyz="0 1 0" />
  </joint>


  


  <ros2_control name="GazeboSystem" type="system">
  <hardware>
      <plugin>gazebo_ros2_control/GazeboSystem</plugin>
  </hardware>

  <joint name="drive_wheel_1_joint">
      <command_interface name="velocity">
          <param name="min">-100.0</param>
          <param name="max">100.0</param>
      </command_interface>
      <state_interface name="position"/>
      <state_interface name="velocity"/>
  </joint>

  <joint name="drive_wheel_2_joint">
      <command_interface name="velocity">
          <param name="min">-100.0</param>
          <param name="max">100.0</param>
      </command_interface>
      <state_interface name="position"/>
      <state_interface name="velocity"/>
  </joint>

  <joint name="steering_joint_1">
        <command_interface name="position">
            <param name="min">-3.14</param>
            <param name="max">3.14</param>
        </command_interface>
        <state_interface name="position"/>
        <state_interface name="velocity"/>
    </joint>

    <joint name="steering_joint_2">
        <command_interface name="position">
            <param name="min">-3.14</param>
            <param name="max">3.14</param>
        </command_interface>
        <state_interface name="position"/>
        <state_interface name="velocity"/>
    </joint>
  
  </ros2_control>



  <gazebo>
      <plugin filename="libgazebo_ros2_control.so" name="gazebo_ros2_control">
          <parameters>$(find project_1_group_2)/config/control.yaml</parameters>
      </plugin>
  </gazebo>

  <gazebo reference="base_link">
    <xacro:red_color />
  </gazebo>
  
  <gazebo reference="steering_wheel_1">
    <xacro:red_color />
  </gazebo>

  <gazebo reference="steering_wheel_2">
    <xacro:red_color />
  </gazebo>

  <gazebo reference="wheel_1">
    <xacro:grey_color />
  </gazebo>

  <gazebo reference="wheel_2">
    <xacro:grey_color />
  </gazebo>

  <gazebo reference="tire_1">
    <xacro:black_color />
  </gazebo>

  <gazebo reference="tire_2">
    <xacro:black_color />
  </gazebo>

  <gazebo reference="drive_wheel_1">
    <xacro:grey_color />
  </gazebo>

  <gazebo reference="drive_wheel_2">
    <xacro:grey_color />
  </gazebo>

  <gazebo reference="drive_tire_1">
    <xacro:black_color />
  </gazebo>

  <gazebo reference="drive_tire_2">
    <xacro:black_color />
  </gazebo>

  <gazebo reference="trailer">
    <xacro:red_color />
  </gazebo>

  <gazebo reference="trailer_axle">
    <xacro:grey_color />
  </gazebo>

  <gazebo reference="trailer_wheel_1">
    <xacro:black_color />
  </gazebo>

  <gazebo reference="trailer_wheel_2">
    <xacro:black_color />
  </gazebo>

  <gazebo reference="lidar_link">
    <xacro:black_color />
  </gazebo>

  <gazebo reference="lidar_link">
  <sensor name="lidar" type="ray">
    <pose>0.0 0.0 0.0 1.57 0 0</pose>
    <always_on>true</always_on>
    <visualize>true</visualize>
    <update_rate>5</update_rate>
    <ray>
      <scan>
        <horizontal>
          <samples>30</samples>
          <resolution>1.00000</resolution>
          <min_angle>0.000000</min_angle>
          <max_angle>6.280000</max_angle>
        </horizontal>
      </scan>
      <range>
        <min>0.120000</min>
        <max>3.5</max>
        <resolution>0.015000</resolution>
      </range>
      <noise>
        <type>gaussian</type>
        <mean>0.0</mean>
        <stddev>0.01</stddev>
      </noise>
    </ray>
    <plugin name="scan" filename="libgazebo_ros_ray_sensor.so">
      <ros>
        <remapping>~/out:=scan</remapping>
      </ros>
      <output_type>sensor_msgs/LaserScan</output_type>
      <frame_name>lidar_link</frame_name>
    </plugin>
  </sensor>
  </gazebo>

</robot>