<?xml version="1.0" ?>
<!-- This URDF was automatically created by SolidWorks to URDF Exporter! Originally created by Stephen Brawner (brawner@gmail.com) 
     Commit Version: 1.6.0-4-g7f85cfe  Build Version: 1.6.7995.38578
     For more information, please see http://wiki.ros.org/sw_urdf_exporter -->
<robot
  name="project_1_group_2" xmlns:xacro="http://ros.org/wiki/xacro">




  <xacro:macro name="red_color">
      <visual>
      <material>
          <ambient>1 0.168627450980392 0.168627450980392 1</ambient>
          <diffuse>1 0.168627450980392 0.168627450980392 1</diffuse>
          <specular>0.1 0.1 0.1 1</specular>
          <emissive>0 0 0 0</emissive>
      </material>
      </visual>
  </xacro:macro>
  
  <xacro:macro name="grey_color">
      <visual>
      <material>
          <ambient>0.8 0.558823529411765 0.1 1</ambient>
          <diffuse>0.8 0.558823529411765 0.1 1</diffuse>
          <specular>0.1 0.1 0.1 1</specular>
          <emissive>0 0 0 0</emissive>
      </material>
      </visual>
  </xacro:macro>

  <xacro:macro name="black_color">
      <visual>
      <material>
          <ambient>0.6 0.6 0.6 1</ambient>
          <diffuse>0.6 0.6 0.6 1</diffuse>
          <specular>0.1 0.1 0.1 1</specular>
          <emissive>0 0 0 0</emissive>
      </material>
      </visual>
  </xacro:macro>


  
  
  <link
    name="base_link">
    <inertial>
      <origin
        xyz="0.219542185844718 -0.489097435985613 0.253171163731009"
        rpy="0 0 0" />
      <mass
        value="45.0255547584039" />
      <inertia
        ixx="3.47370213259269"
        ixy="8.68638754776676E-06"
        ixz="1.2881777172653E-06"
        iyy="1.51493007257673"
        iyz="0.0559660105211113"
        izz="4.32787408102169" />
    </inertial>
    <visual>
      <origin
        xyz="0 0 0"
        rpy="0 0 0" />
      <geometry>
        <mesh
          filename="package://project_1_group_2/meshes/base_link.STL" />
      </geometry>
      <material
        name="">
        <color
          rgba="1 0.168627450980392 0.168627450980392 1" />
      </material>
    </visual>
    <collision>
      <origin
        xyz="0 0 0"
        rpy="0 0 0" />
      <geometry>
        <mesh
          filename="package://project_1_group_2/meshes/base_link.STL" />
      </geometry>
    </collision>
  </link>
  <link
    name="steering_wheel_1">
    <inertial>
      <origin
        xyz="2.8607507807088E-08 0.0723663419355983 0.0025405194968964"
        rpy="0 0 0" />
      <mass
        value="0.295424107267105" />
      <inertia
        ixx="0.000710809060839364"
        ixy="1.53957020724956E-10"
        ixz="3.53322320619659E-10"
        iyy="0.000104054571155282"
        iyz="3.85934455800398E-05"
        izz="0.00069010101560226" />
    </inertial>
    <visual>
      <origin
        xyz="0 0 0"
        rpy="0 0 0" />
      <geometry>
        <mesh
          filename="package://project_1_group_2/meshes/steering_wheel_1.STL" />
      </geometry>
      <material
        name="">
        <color
          rgba="1 0.168627450980392 0.168627450980392 1" />
      </material>
    </visual>
    <collision>
      <origin
        xyz="0 0 0"
        rpy="0 0 0" />
      <geometry>
        <mesh
          filename="package://project_1_group_2/meshes/steering_wheel_1.STL" />
      </geometry>
    </collision>
  </link>
  <joint
    name="steering_joint_1"
    type="revolute">
    <origin
      xyz="0.070952 -0.7342 0.038134"
      rpy="1.5708 0 -1.6485" />
    <parent
      link="base_link" />
    <child
      link="steering_wheel_1" />
    <axis
      xyz="0 1 0" />
    <limit
      lower="-3.14"
      upper="3.14"
      effort="100"
      velocity="100" />
  </joint>
  <link
    name="wheel_1">
    <inertial>
      <origin
        xyz="-0.00233208035893656 0.0353869418204771 0.00100647960707934"
        rpy="0 0 0" />
      <mass
        value="0.217134053712094" />
      <inertia
        ixx="0.000126052696684197"
        ixy="-6.05628557286825E-20"
        ixz="-3.3881317890172E-21"
        iyy="0.000159854355976214"
        iyz="-1.27901975035399E-19"
        izz="0.000126052696684197" />
    </inertial>
    <visual>
      <origin
        xyz="0 0 0"
        rpy="0 0 0" />
      <geometry>
        <mesh
          filename="package://project_1_group_2/meshes/wheel_1.STL" />
      </geometry>
      <material
        name="">
        <color
          rgba="0.498039215686275 0.498039215686275 0.498039215686275 1" />
      </material>
    </visual>
    <collision>
      <origin
        xyz="0 0 0"
        rpy="0 0 0" />
      <geometry>
        <mesh
          filename="package://project_1_group_2/meshes/wheel_1.STL" />
      </geometry>
    </collision>
  </link>
  <joint
    name="wheel_1_joint"
    type="continuous">
    <origin
      xyz="0 0.023495 0.030481"
      rpy="1.5708 0 1.1634" />
    <parent
      link="steering_wheel_1" />
    <child
      link="wheel_1" />
    <axis
      xyz="0 1 0" />
  </joint>
  <link
    name="tire_1">
    <inertial>
      <origin
        xyz="-0.00233208035893662 0.0356826852487729 0.00099954289455717"
        rpy="0 0 0" />
      <mass
        value="1.9636352752673" />
      <inertia
        ixx="0.00664149361787531"
        ixy="-5.28548559086683E-18"
        ixz="-4.33680868994202E-19"
        iyy="0.0114725337233255"
        iyz="5.01717636383912E-07"
        izz="0.00664244711710664" />
    </inertial>
    <visual>
      <origin
        xyz="0 0 0"
        rpy="0 0 0" />
      <geometry>
        <mesh
          filename="package://project_1_group_2/meshes/tire_1.STL" />
      </geometry>
      <material
        name="">
        <color
          rgba="0.6 0.6 0.6 1" />
      </material>
    </visual>
    <collision>
      <origin
        xyz="0 0 0"
        rpy="0 0 0" />
      <geometry>
        <mesh
          filename="package://project_1_group_2/meshes/tire_1.STL" />
      </geometry>
    </collision>
  </link>
  <joint
    name="tire_joint_1"
    type="fixed">
    <origin
      xyz="0 0 0"
      rpy="0 0 0" />
    <parent
      link="wheel_1" />
    <child
      link="tire_1" />
    <axis
      xyz="0 0 0" />
  </joint>
  <link
    name="steering_wheel_2">
    <inertial>
      <origin
        xyz="2.86075080291326E-08 0.0723663419355979 0.0025405194968961"
        rpy="0 0 0" />
      <mass
        value="0.295424107267104" />
      <inertia
        ixx="0.000710809060839366"
        ixy="1.53957022022187E-10"
        ixz="3.53322320463805E-10"
        iyy="0.000104054571155282"
        iyz="3.85934455800392E-05"
        izz="0.000690101015602263" />
    </inertial>
    <visual>
      <origin
        xyz="0 0 0"
        rpy="0 0 0" />
      <geometry>
        <mesh
          filename="package://project_1_group_2/meshes/steering_wheel_2.STL" />
      </geometry>
      <material
        name="">
        <color
          rgba="1 0.168627450980392 0.168627450980392 1" />
      </material>
    </visual>
    <collision>
      <origin
        xyz="0 0 0"
        rpy="0 0 0" />
      <geometry>
        <mesh
          filename="package://project_1_group_2/meshes/steering_wheel_2.STL" />
      </geometry>
    </collision>
  </link>
  <joint
    name="steering_joint_2"
    type="revolute">
    <origin
      xyz="0.36813 -0.7342 0.038134"
      rpy="1.5708 0 1.4699" />
    <parent
      link="base_link" />
    <child
      link="steering_wheel_2" />
    <axis
      xyz="0 1 0" />
    <limit
      lower="-3.14"
      upper="3.14"
      effort="100"
      velocity="100" />
  </joint>
  <link
    name="wheel_2">
    <inertial>
      <origin
        xyz="-3.33066907387547E-16 0.0352804142384009 0.00254000000000009"
        rpy="0 0 0" />
      <mass
        value="0.217134053712094" />
      <inertia
        ixx="0.000126052696684198"
        ixy="-1.42301535138722E-19"
        ixz="3.17002825963484E-22"
        iyy="0.000159854355976214"
        iyz="4.53198898728574E-20"
        izz="0.000126052696684198" />
    </inertial>
    <visual>
      <origin
        xyz="0 0 0"
        rpy="0 0 0" />
      <geometry>
        <mesh
          filename="package://project_1_group_2/meshes/wheel_2.STL" />
      </geometry>
      <material
        name="">
        <color
          rgba="0.498039215686275 0.498039215686275 0.498039215686275 1" />
      </material>
    </visual>
    <collision>
      <origin
        xyz="0 0 0"
        rpy="0 0 0" />
      <geometry>
        <mesh
          filename="package://project_1_group_2/meshes/wheel_2.STL" />
      </geometry>
    </collision>
  </link>
  <joint
    name="wheel_2_joint"
    type="continuous">
    <origin
      xyz="0 0.023495 0.030587184793973"
      rpy="1.5707963267949 0 0" />
    <parent
      link="steering_wheel_2" />
    <child
      link="wheel_2" />
    <axis
      xyz="0 1 0" />
  </joint>
  <link
    name="tire_2">
    <inertial>
      <origin
        xyz="-1.11022302462516E-16 0.0355761576666964 0.002533063287478"
        rpy="0 0 0" />
      <mass
        value="1.9636352752673" />
      <inertia
        ixx="0.00664149361787531"
        ixy="-2.24429849704499E-17"
        ixz="-1.96935160236779E-20"
        iyy="0.0114725337233255"
        iyz="5.01717636407577E-07"
        izz="0.00664244711710664" />
    </inertial>
    <visual>
      <origin
        xyz="0 0 0"
        rpy="0 0 0" />
      <geometry>
        <mesh
          filename="package://project_1_group_2/meshes/tire_2.STL" />
      </geometry>
      <material
        name="">
        <color
          rgba="0.6 0.6 0.6 1" />
      </material>
    </visual>
    <collision>
      <origin
        xyz="0 0 0"
        rpy="0 0 0" />
      <geometry>
        <mesh
          filename="package://project_1_group_2/meshes/tire_2.STL" />
      </geometry>
    </collision>
  </link>
  <joint
    name="tire_2_joint"
    type="fixed">
    <origin
      xyz="0 0 0"
      rpy="0 0 0" />
    <parent
      link="wheel_2" />
    <child
      link="tire_2" />
    <axis
      xyz="0 0 0" />
  </joint>
  <link
    name="drive_wheel_1">
    <inertial>
      <origin
        xyz="-3.46944695195361E-17 -0.00140110038134092 2.77555756156289E-17"
        rpy="0 0 0" />
      <mass
        value="0.217134053712094" />
      <inertia
        ixx="0.000126052696684197"
        ixy="3.65602981705437E-21"
        ixz="-1.01643953670516E-20"
        iyy="0.000159854355976214"
        iyz="-7.36513260038282E-22"
        izz="0.000126052696684197" />
    </inertial>
    <visual>
      <origin
        xyz="0 0 0"
        rpy="0 0 0" />
      <geometry>
        <mesh
          filename="package://project_1_group_2/meshes/drive_wheel_1.STL" />
      </geometry>
      <material
        name="">
        <color
          rgba="0.498039215686275 0.498039215686275 0.498039215686275 1" />
      </material>
    </visual>
    <collision>
      <origin
        xyz="0 0 0"
        rpy="0 0 0" />
      <geometry>
        <mesh
          filename="package://project_1_group_2/meshes/drive_wheel_1.STL" />
      </geometry>
    </collision>
  </link>
  <joint
    name="drive_wheel_1_joint"
    type="continuous">
    <origin
      xyz="0 -0.2262 0.061675"
      rpy="0 -1.0561 1.5708" />
    <parent
      link="base_link" />
    <child
      link="drive_wheel_1" />
    <axis
      xyz="0 1 0" />
      <limit
      effort="100"
      velocity="1000"
      />
  </joint>
  <link
    name="drive_tire_1">
    <inertial>
      <origin
        xyz="2.08166817117217E-17 0.048894643046955 -6.93671252216532E-06"
        rpy="0 0 0" />
      <mass
        value="1.9636352752673" />
      <inertia
        ixx="0.00664149361787532"
        ixy="6.09863722023096E-19"
        ixz="6.50521303491303E-19"
        iyy="0.0114725337233256"
        iyz="5.01717636401377E-07"
        izz="0.00664244711710664" />
    </inertial>
    <visual>
      <origin
        xyz="0 0 0"
        rpy="0 0 0" />
      <geometry>
        <mesh
          filename="package://project_1_group_2/meshes/drive_tire_1.STL" />
      </geometry>
      <material
        name="">
        <color
          rgba="0.6 0.6 0.6 1" />
      </material>
    </visual>
    <collision>
      <origin
        xyz="0 0 0"
        rpy="0 0 0" />
      <geometry>
        <mesh
          filename="package://project_1_group_2/meshes/drive_tire_1.STL" />
      </geometry>
    </collision>
  </link>
  <joint
    name="drive_tire_joint"
    type="fixed">
    <origin
      xyz="0 -0.05 0"
      rpy="0 0 0" />
    <parent
      link="drive_wheel_1" />
    <child
      link="drive_tire_1" />
    <axis
      xyz="0 0 0" />
  </joint>
  <link
    name="drive_wheel_2">
    <inertial>
      <origin
        xyz="-2.77555756156289E-17 0.0276405990323743 0"
        rpy="0 0 0" />
      <mass
        value="0.217134053712094" />
      <inertia
        ixx="0.000126052696684198"
        ixy="-3.68451216035455E-22"
        ixz="3.3881317890172E-21"
        iyy="0.000159854355976214"
        iyz="4.59516996223815E-21"
        izz="0.000126052696684198" />
    </inertial>
    <visual>
      <origin
        xyz="0 0 0"
        rpy="0 0 0" />
      <geometry>
        <mesh
          filename="package://project_1_group_2/meshes/drive_wheel_2.STL" />
      </geometry>
      <material
        name="">
        <color
          rgba="0.498039215686275 0.498039215686275 0.498039215686275 1" />
      </material>
    </visual>
    <collision>
      <origin
        xyz="0 0 0"
        rpy="0 0 0" />
      <geometry>
        <mesh
          filename="package://project_1_group_2/meshes/drive_wheel_2.STL" />
      </geometry>
    </collision>
  </link>
  <joint
    name="drive_wheel_2_joint"
    type="continuous">
    <origin
      xyz="0.41004 -0.2262 0.061675"
      rpy="0 0.13365 -1.5708" />
    <parent
      link="base_link" />
    <child
      link="drive_wheel_2" />
    <axis
      xyz="0 1 0" />
      <limit
      effort="100"
      velocity="1000"
      />
  </joint>
  <link
    name="drive_tire_2">
    <inertial>
      <origin
        xyz="1.11022302462516E-16 0.0406363424606702 -6.93671252208206E-06"
        rpy="0 0 0" />
      <mass
        value="1.9636352752673" />
      <inertia
        ixx="0.00664149361787531"
        ixy="-2.07046616044473E-19"
        ixz="-1.62630325872826E-19"
        iyy="0.0114725337233255"
        iyz="5.01717636401017E-07"
        izz="0.00664244711710664" />
    </inertial>
    <visual>
      <origin
        xyz="0 0 0"
        rpy="0 0 0" />
      <geometry>
        <mesh
          filename="package://project_1_group_2/meshes/drive_tire_2.STL" />
      </geometry>
      <material
        name="">
        <color
          rgba="0.6 0.6 0.6 1" />
      </material>
    </visual>
    <collision>
      <origin
        xyz="0 0 0"
        rpy="0 0 0" />
      <geometry>
        <mesh
          filename="package://project_1_group_2/meshes/drive_tire_2.STL" />
      </geometry>
    </collision>
  </link>
  <joint
    name="drive_tire_2_joint"
    type="fixed">
    <origin
      xyz="0 -0.0127 0"
      rpy="3.14159265358979 0 3.14159265358979" />
    <parent
      link="drive_wheel_2" />
    <child
      link="drive_tire_2" />
    <axis
      xyz="0 0 0" />
  </joint>
  <link
    name="trailer">
    <inertial>
      <origin
        xyz="1.03723919092635E-07 0.039678899062889 0.429404896824893"
        rpy="0 0 0" />
      <mass
        value="5.43041573976378" />
      <inertia
        ixx="0.10730066092027"
        ixy="3.55141031738537E-09"
        ixz="1.34013193767086E-07"
        iyy="0.205190385513249"
        iyz="-0.00161014497039631"
        izz="0.111162712366413" />
    </inertial>
    <visual>
      <origin
        xyz="0 0 0"
        rpy="0 0 0" />
      <geometry>
        <mesh
          filename="package://project_1_group_2/meshes/trailer.STL" />
      </geometry>
      <material
        name="">
        <color
          rgba="1 0.168627450980392 0.168627450980392 1" />
      </material>
    </visual>
    <collision>
      <origin
        xyz="0 0 0"
        rpy="0 0 0" />
      <geometry>
        <mesh
          filename="package://project_1_group_2/meshes/trailer.STL" />
      </geometry>
    </collision>
  </link>
  <joint
    name="trailer_joint"
    type="continuous">
    <origin
      xyz="0.21954 0.075693 0.11822"
      rpy="1.5708 0 3.1416" />
    <parent
      link="base_link" />
    <child
      link="trailer" />
    <axis
      xyz="0 0 1" />
  </joint>
  <link
    name="trailer_axle">
    <inertial>
      <origin
        xyz="-2.77555756156289E-17 1.11022302462516E-16 -1.11022302462516E-16"
        rpy="0 0 0" />
      <mass
        value="0.388537069771013" />
      <inertia
        ixx="0.00709487470732703"
        ixy="-3.22345840493327E-19"
        ixz="0"
        iyy="5.66992976163243E-05"
        iyz="-1.06353893196349E-19"
        izz="0.00709487470732703" />
    </inertial>
    <visual>
      <origin
        xyz="0 0 0"
        rpy="0 0 0" />
      <geometry>
        <mesh
          filename="package://project_1_group_2/meshes/trailer_axle.STL" />
      </geometry>
      <material
        name="">
        <color
          rgba="0.498039215686275 0.498039215686275 0.498039215686275 1" />
      </material>
    </visual>
    <collision>
      <origin
        xyz="0 0 0"
        rpy="0 0 0" />
      <geometry>
        <mesh
          filename="package://project_1_group_2/meshes/trailer_axle.STL" />
      </geometry>
    </collision>
  </link>
  <joint
    name="trailer_axle_joint"
    type="continuous">
    <origin
      xyz="0 -0.0513467524152484 0.444499999999999"
      rpy="0 -0.538949692004303 -1.5707963267949" />
    <parent
      link="trailer" />
    <child
      link="trailer_axle" />
    <axis
      xyz="0 1 0" />
  </joint>
  <link
    name="trailer_wheel_1">
    <inertial>
      <origin
        xyz="-1.11022302462516E-16 2.22044604925031E-16 0.0190500000000002"
        rpy="0 0 0" />
      <mass
        value="1.30378374657888" />
      <inertia
        ixx="0.00396064889398226"
        ixy="3.25260651745651E-19"
        ixz="1.83643208229129E-19"
        iyy="0.00396064889398226"
        iyz="3.13874282267138E-19"
        izz="0.00761008083736416" />
    </inertial>
    <visual>
      <origin
        xyz="0 0 0"
        rpy="0 0 0" />
      <geometry>
        <mesh
          filename="package://project_1_group_2/meshes/trailer_wheel_1.STL" />
      </geometry>
      <material
        name="">
        <color
          rgba="0.6 0.6 0.6 1" />
      </material>
    </visual>
    <collision>
      <origin
        xyz="0 0 0"
        rpy="0 0 0" />
      <geometry>
        <mesh
          filename="package://project_1_group_2/meshes/trailer_wheel_1.STL" />
      </geometry>
    </collision>
  </link>
  <joint
    name="trailer_wheel_1_joint"
    type="fixed">
    <origin
      xyz="0 0.2159 0"
      rpy="-1.5707963267949 0 0" />
    <parent
      link="trailer_axle" />
    <child
      link="trailer_wheel_1" />
    <axis
      xyz="0 0 0" />
  </joint>
  <link
    name="trailer_wheel_2">
    <inertial>
      <origin
        xyz="1.38777878078145E-16 2.22044604925031E-16 0.0190500000000002"
        rpy="0 0 0" />
      <mass
        value="1.30378374657888" />
      <inertia
        ixx="0.00396064889398226"
        ixy="-5.42101086242752E-19"
        ixz="2.3648274839026E-19"
        iyy="0.00396064889398226"
        iyz="-4.01472956762225E-19"
        izz="0.00761008083736416" />
    </inertial>
    <visual>
      <origin
        xyz="0 0 0"
        rpy="0 0 0" />
      <geometry>
        <mesh
          filename="package://project_1_group_2/meshes/trailer_wheel_2.STL" />
      </geometry>
      <material
        name="">
        <color
          rgba="0.6 0.6 0.6 1" />
      </material>
    </visual>
    <collision>
      <origin
        xyz="0 0 0"
        rpy="0 0 0" />
      <geometry>
        <mesh
          filename="package://project_1_group_2/meshes/trailer_wheel_2.STL" />
      </geometry>
    </collision>
  </link>
  <joint
    name="trailer_wheel_2_joint"
    type="fixed">
    <origin
      xyz="0 -0.2159 0"
      rpy="-1.5707963267949 0 3.14159265358979" />
    <parent
      link="trailer_axle" />
    <child
      link="trailer_wheel_2" />
    <axis
      xyz="0 0 0" />
  </joint>
  <link
    name="lidar_link">
    <inertial>
      <origin
        xyz="0 0.00126999999999999 0"
        rpy="0 0 0" />
      <mass
        value="0.00514814798763055" />
      <inertia
        ixx="8.33112604888014E-07"
        ixy="-3.20922964057601E-40"
        ixz="0"
        iyy="1.66068957784986E-06"
        iyz="2.8186396765545E-40"
        izz="8.33112604888014E-07" />
    </inertial>
    <visual>
      <origin
        xyz="0 0 0"
        rpy="0 0 0" />
      <geometry>
        <mesh
          filename="package://project_1_group_2/meshes/lidar_link.STL" />
      </geometry>
      <material
        name="">
        <color
          rgba="0.792156862745098 0.819607843137255 0.933333333333333 1" />
      </material>
    </visual>
    <collision>
      <origin
        xyz="0 0 0"
        rpy="0 0 0" />
      <geometry>
        <mesh
          filename="package://project_1_group_2/meshes/lidar_link.STL" />
      </geometry>
    </collision>
  </link>
  <joint
    name="lidar_joint"
    type="continuous">
    <origin
      xyz="0.219541699413715 -0.521188368096002 0.439623181973066"
      rpy="1.5707963267949 0 0" />
    <parent
      link="base_link" />
    <child
      link="lidar_link" />
    <axis
      xyz="0 1 0" />
  </joint>



  <ros2_control name="GazeboSystem" type="system">
  <hardware>
      <plugin>gazebo_ros2_control/GazeboSystem</plugin>
  </hardware>

  <joint name="drive_wheel_1_joint">
      <command_interface name="velocity">
          <param name="min">-100.0</param>
          <param name="max">100.0</param>
      </command_interface>
      <state_interface name="position"/>
      <state_interface name="velocity"/>
  </joint>

  <joint name="drive_wheel_2_joint">
      <command_interface name="velocity">
          <param name="min">-100.0</param>
          <param name="max">100.0</param>
      </command_interface>
      <state_interface name="position"/>
      <state_interface name="velocity"/>
  </joint>

  <joint name="steering_joint_1">
        <command_interface name="position">
            <param name="min">-3.14</param>
            <param name="max">3.14</param>
        </command_interface>
        <state_interface name="position"/>
        <state_interface name="velocity"/>
    </joint>

    <joint name="steering_joint_2">
        <command_interface name="position">
            <param name="min">-3.14</param>
            <param name="max">3.14</param>
        </command_interface>
        <state_interface name="position"/>
        <state_interface name="velocity"/>
    </joint>
  
  </ros2_control>



  <gazebo>
      <plugin filename="libgazebo_ros2_control.so" name="gazebo_ros2_control">
          <parameters>$(find project_1_group_2)/config/control.yaml</parameters>
      </plugin>
  </gazebo>

  <gazebo reference="base_link">
    <xacro:red_color />
  </gazebo>
  
  <gazebo reference="steering_wheel_1">
    <xacro:red_color />
  </gazebo>

  <gazebo reference="steering_wheel_2">
    <xacro:red_color />
  </gazebo>

  <gazebo reference="wheel_1">
    <xacro:grey_color />
  </gazebo>

  <gazebo reference="wheel_2">
    <xacro:grey_color />
  </gazebo>

  <gazebo reference="tire_1">
    <xacro:black_color />
  </gazebo>

  <gazebo reference="tire_2">
    <xacro:black_color />
  </gazebo>

  <gazebo reference="drive_wheel_1">
    <xacro:grey_color />
  </gazebo>

  <gazebo reference="drive_wheel_2">
    <xacro:grey_color />
  </gazebo>

  <gazebo reference="drive_tire_1">
    <xacro:black_color />
  </gazebo>

  <gazebo reference="drive_tire_2">
    <xacro:black_color />
  </gazebo>

  <gazebo reference="trailer">
    <xacro:red_color />
  </gazebo>

  <gazebo reference="trailer_axle">
    <xacro:grey_color />
  </gazebo>

  <gazebo reference="trailer_wheel_1">
    <xacro:black_color />
  </gazebo>

  <gazebo reference="trailer_wheel_2">
    <xacro:black_color />
  </gazebo>

  <gazebo reference="lidar_link">
    <xacro:black_color />
  </gazebo>

  <gazebo reference="lidar_link">
  <sensor name="lidar" type="ray">
    <pose>0.0 0.0 0.0 1.57 0 0</pose>
    <always_on>true</always_on>
    <visualize>true</visualize>
    <update_rate>5</update_rate>
    <ray>
      <scan>
        <horizontal>
          <samples>360</samples>
          <resolution>1.00000</resolution>
          <min_angle>0.000000</min_angle>
          <max_angle>6.280000</max_angle>
        </horizontal>
      </scan>
      <range>
        <min>0.120000</min>
        <max>3.5</max>
        <resolution>0.015000</resolution>
      </range>
      <noise>
        <type>gaussian</type>
        <mean>0.0</mean>
        <stddev>0.01</stddev>
      </noise>
    </ray>
    <plugin name="scan" filename="libgazebo_ros_ray_sensor.so">
      <ros>
        <remapping>~/out:=scan</remapping>
      </ros>
      <output_type>sensor_msgs/LaserScan</output_type>
      <frame_name>lidar_link</frame_name>
    </plugin>
  </sensor>
  </gazebo>

</robot>